Workbook

Sheet REGISTRO DE PERSONAL
D1: PROCESOS DE REGISTRO DE PERSONAL
B2: *PENSADO PARA PERSONAL QUE COBRA X MES Y POR SEMANA | D2: Entrevista
D3: Prueba (3 días) - resultado
D4: Registro de datos de personal
D5: Documentacion de personal
D6: Acuerdos de Contrado
E7: horarios
E8: sueldos
E9: metas
E10: funciones
D11: Registro de asistencias
D12: Registro automatico de las ventas mayores a 120 y las semanales ( 4 etapas)
D13: Registro de adelantos
D14: registro de Reportes con descuento
D15: Registro de justificaciones
D16: Registro de Calculo de sueldo
D17: Nota Mensual de Colaboradaror y su resumen
D18: Observacione sde personal
D19: Que falta regularizar para sacar su cuenta
D20: Resumen informativo mensual

Sheet DASHWORD
A1: TOTAL DE DÍAS | B1: DÍA | C1: HORA DE INGRESO | D1: HORA DE SALIDA | E1: LUGAR | F1: CANTIDAD DE HORAS | G1: HORAS EN FORMATO NÚMEROS | H1: HORAS EN FORMATO HORAS | I1: HORAS POR DÍAS DE LA SEMANA | J1: COMISIONES | K1: -Comisiones del 2% para boletas mayores a (s/.120,00) -Por cumplimiento de metas semanales (s/.30,00) | P1: TOTAL DE TARDANZAS | Q1: =COUNTIF(E25:E55,">9:10") -> 11
A2: =COUNTIF($A$25:$A$55,1) -> 5 | B2: LUNES | C2: 0.375 | D2: 0.54166667 | E2: ESQUINA | F2: =IFERROR((D2-C2)*24,0) -> 4 | G2: =IFERROR(F2+F3,0) -> 11 | H2: =IFERROR(D2-C2,0)+IFERROR(D3-C3,0) -> 0.45833333 | I2: =A2*G2 -> 55 | J2: ADICIONALES | K2: - Almuerzo los días completo que se queda | P2: Justificadas X defecto 3 | Q2: 3
B3: LUNES | C3: 0.54166667 | D3: 0.83333333 | E3: ESQUINA | F3: =IFERROR((D3-C3)*24,0) -> 7 | J3: TOLERANCIA DE INGRESO | K3: 10 MINUTOS | P3: Justificadas x el colaborador | Q3: 4 | R3: LO RELLENA EL ADMINISTRADOR | T3: Horas de trabajos totales al mes | U3: =B20 -> 165
A4: =COUNTIF($A$25:$A$55,2) -> 5 | B4: MARTES | C4: 0.375 | D4: 0.54166667 | E4: ESQUINA | F4: =IFERROR((D4-C4)*24,0) -> 4 | G4: =IFERROR(F4+F5,0) -> 11 | H4: =IFERROR(D4-C4,0)+IFERROR(D5-C5,0) -> 0.45833333 | I4: =A4*G4 -> 55 | P4: Injustificadas | Q4: =Q1-Q2-Q3 -> 4 | T4: Meta para este mes | U4: =U3*PARAMETROS!G5 -> 7500
B5: MARTES | C5: 0.54166667 | D5: 0.83333333 | E5: ESQUINA | F5: =IFERROR((D5-C5)*24,0) -> 7 | J5: *modificar los adicionales en en horas | P5: domingos | T5: Horas Semanales | U5: =B19 -> 33
A6: =COUNTIF($A$25:$A$55,3) -> 5 | B6: MIERCOLES | C6: 0.375 | D6: 0.54166667 | E6: ESQUINA | F6: =IFERROR((D6-C6)*24,0) -> 4 | G6: =IFERROR(F6+F7,0) -> 11 | H6: =IFERROR(D6-C6,0)+IFERROR(D7-C7,0) -> 0.45833333 | I6: =A6*G6 -> 55 | P6: Total de tardanzas a descontar | Q6: =(Q4+Q5)*5 -> 20 | T6: Meta Semanal | U6: =U5*PARAMETROS!G5 -> 1500 | V6: =U6*4 -> 6000
B7: MIERCOLES | C7: 0.54166667 | D7: 0.83333333 | E7: ESQUINA | F7: =IFERROR((D7-C7)*24,0) -> 7 | P7: TOTAL DE FALTAS | Q7: =COUNTIF(E25:E55,"=0:00") -> 0 | T7: Meta Semanal DESIGNADA | U7: =U6*85% -> 1275 | V7: =U7*4 -> 5100
A8: =COUNTIF($A$25:$A$55,4) -> 4 | B8: JUEVES | C8: - | D8: - | E8: DESCANSO | F8: =IFERROR((D8-C8)*24,0) -> 0 | G8: =IFERROR(F8+F9,0) -> 0 | H8: =IFERROR(D8-C8,0)+IFERROR(D9-C9,0) -> 0 | I8: =A8*G8 -> 0 | P8: justificadas | Q8: 0 | R8: LO RELLENA EL ADMINISTRADOR
B9: JUEVES | C9: - | D9: - | E9: ESQUINA | F9: =IFERROR((D9-C9)*24,0) -> 0 | J9: =F2+F3 -> 11 | P9: injustificadas | Q9: =Q7-Q8 -> 0
A10: =COUNTIF($A$25:$A$55,5) -> 4 | B10: VIERNES | C10: - | D10: - | E10: stan 101 | F10: =IFERROR((D10-C10)*24,0) -> 0 | G10: =IFERROR(F10+F11,0) -> 0 | H10: =IFERROR(D10-C10,0)+IFERROR(D11-C11,0) -> 0 | I10: =A10*G10 -> 0 | P10: TOTAL DE DIAS INJUSTIFICADOS X DESCONTAR | Q10: =Q9 -> 0 | Z10: FECHAS | AA10: FECHAS | AB10: FECHAS | AC10: FECHAS
B11: VIERNES | C11: - | D11: - | E11: ESQUINA | F11: =IFERROR((D11-C11)*24,0) -> 0 | K11: 470 | P11: METAS SEMANALES CUMPLIDAS | Q11: 3 | R11: LO RELLENA EL ADMINISTRADOR | Y11: DE | Z11: =D25 -> 45824 | AA11: =D32 -> 45831 | AB11: =D39 -> 45838 | AC11: =D46 -> 45845
A12: =COUNTIF($A$25:$A$55,6) -> 4 | B12: SÁBADO | C12: - | D12: - | E12: ESQUINA | F12: =IFERROR((D12-C12)*24,0) -> 0 | G12: =IFERROR(F12+F13,0) -> 0 | H12: =IFERROR(D12-C12,0)+IFERROR(D13-C13,0) -> 0 | I12: =A12*G12 -> 0 | P12: ALMUERZOS PAGADOS | Q12: 8 | R12: LO RELLENA EL ADMINISTRADOR | T12: VENTAS POR MESS | Y12: HASTA | Z12: =D31 -> 45830 | AA12: =D38 -> 45837 | AB12: =D45 -> 45844 | AC12: =D52 -> 45851
B13: SÁBADO | C13: - | D13: - | E13: ESQUINA | F13: =IFERROR((D13-C13)*24,0) -> 0 | P13: CANTIDAD DE PERSONAS CAPACITADAS | Q13: 2 | R13: LO RELLENA EL ADMINISTRADOR | T13: TIENDAS | U13: VENTAS | V13: ALQUILER | X13: VENTAS POR SEMANA
A14: =COUNTIF($A$25:$A$55,7) -> 4 | B14: DOMINGO | C14: - | D14: - | E14: ESQUINA | F14: =IFERROR((D14-C14)*24,0) -> 0 | G14: =IFERROR(F14+F15,0) -> 0 | H14: =IFERROR(D14-C14,0)+IFERROR(D15-C15,0) -> 0 | I14: =A14*G14 -> 0 | K14: =514/2.9 -> 177.24138 | P14: ALMUERZOS NO PAGADOS | Q14: =B23-Q12 -> 19 | R14: LO RELLENA EL ADMINISTRADOR | T14: =T24 -> LUCE BIEN 1 (REDENTOR) | U14: 400 | V14: 500 | X14: TIENDAS | Z14: 1RA SEM. | AA14: 2DA SEM. | AB14: 3RA SEM. | AC14: 4TA SEM.
B15: DOMINGO | C15: - | D15: - | E15: ESQUINA | F15: =IFERROR((D15-C15)*24,0) -> 0 | T15: =T30 -> LUCEBIEN 2 (ESQUINA) | U15: 1200 | X15: =T14 -> LUCE BIEN 1 (REDENTOR)
A16: SUELO RECOMENDADO A PERCIBIR | B16: =B18*B20 -> 478.5 | D16: ACUERDOS | K16: SUELDO | O16: FECHA | P16: DESCUENTOS(REPORTES) | R16: MONTO | T16: =T36 -> LUCEBIEN 3 TRECE | U16: 100 | V16: 2000 | X16: =T15 -> LUCEBIEN 2 (ESQUINA)
A17: SUELO RECOMENDADO X DÍA | B17: =B16/B23 -> 17.722222 | D17: METAS SEMANALES DE VENTA PARA COBRAR 30,00 ADICIONAL AL SUELDO | J17: 1650 | K17: MENSUAL | L17: 600 | P17: CIDIGO DE DESCUENTO | Q17: MOTIVOS Y DESCRIPCIÓN | T17: =T42 -> ONLINE | X17: =T16 -> LUCEBIEN 3 TRECE
A18: SUELO RECOMENDADO X HORAS (MODIFICAR MANUAL) | B18: =PARAMETROS!C4 -> 2.9 | D18: META MENSUAL PARA DESBLOQUEAR LAS COMISIONES 2% | J18: 4800 | K18: DIARIO | L18: =L17/B23 -> 22.222222 | P18: g7 | Q18: malogro plancha | R18: 20 | T18: =T48 -> STAN (101- 102) | U18: 100 | X18: =T17 -> ONLINE
A19: TOTAL DE HORAS POR SEMANA | B19: =SUM(G2:G15) -> 33 | K19: HORAS | L19: =L18/L22 -> 3.6363636 | T19: =T54 -> FERIA | X19: =T18 -> STAN (101- 102) | Z19: 1800 | AA19: 1800 | AB19: 1800 | AC19: 1800
A20: TOTAL DE HORAS POR MES | B20: =SUM(I2:I15) -> 165 | K20: x | L20: x | T20: TOTAL | U20: =U14+U15+U16+U17+U18 -> 1800 | V20: =V14+V15+V16+V17+V18 -> 2500 | X20: TOTAL | Z20: =Z15+Z16+Z17+Z18+Z19 -> 1800 | AA20: =AA15+AA16+AA17+AA18+AA19 -> 1800 | AB20: =AB15+AB16+AB17+AB18+AB19 -> 1800 | AC20: =AC15+AC16+AC17+AC18+AC19 -> 1800
A21: TOTAL DE HORAS POR DÍA EN VALOR NUMÉRICO (EN BASE DE 26 DÍAS) | B21: =B20/B23 -> 6.1111111 | K21: HORAS AL MES | L21: =L22*B23 -> 165 | T21: GRAN TOTAL | U21: =U20+V20 -> 4300 | X21: GRAN TOTAL | Z21: =Z20+AA20+AB20+AC20 -> 7200
A22: TOTAL DE HORAS POR DÍA (USAR LA REGLA DE TRES) | B22: x | K22: horas x día | L22: =B21 -> 6.1111111
A23: DÍAS LABORABLES | B23: =A2+A4+A6+A8+A10+A12 -> 27 | K23: x | L23: x | O23: TOTAL PAGADO | R23: =-(R18+R19+R20+R21+R22) -> -20
A24: DIAS SEM | B24: DIAS | C24: DÍA | D24: FECHA | E24: INGRESO | F24: SALIDA | G24: CANTIDAD DE HORAS LABORADAS | H24: HORAS POR DÍA QUE DEBE CUJMPLIR | I24: DIFERENCIA DE HORAS | J24: SUMA Y DESCUENTOS X LA DIFERENCIA DE HORAS | K24: TARDANZAS FALTAS JUSTIFICADAS | L24: OBSERVACIONES | T24: LUCE BIEN 1 (REDENTOR) | AF24: =SUM(U24:AE29) -> 0
A25: =WEEKDAY(D25,2) -> 1 | B25: 1 | C25: =D25 -> 45824 | D25: 45824 | E25: 0.38263889 | F25: 0.85416667 | G25: =F25-E25 -> 0.47152778 | H25: =IF(A25=1,$H$2,IF(A25=2,$H$4,IF(A25=3,$H$6,IF(A25=4,$H$8,IF(A25=5,$H$10,IF(A25=6,$H$12,IF(A25=7,$H$14))))))) -> 0.45833333 | I25: =G25-H25 -> 0.013194444 | J25: =I25*$L$19*24 -> 1.1515152 | O25: ADELANTOS
A26: =WEEKDAY(D26,2) -> 2 | B26: 2 | C26: =D26 -> 45825 | D26: 45825 | E26: 0.38263889 | F26: 0.85416667 | G26: =F26-E26 -> 0.47152778 | H26: =IF(A26=1,$H$2,IF(A26=2,$H$4,IF(A26=3,$H$6,IF(A26=4,$H$8,IF(A26=5,$H$10,IF(A26=6,$H$12,IF(A26=7,$H$14))))))) -> 0.45833333 | I26: =G26-H26 -> 0.013194444 | J26: =I26*$L$19*24 -> 1.1515152 | O26: FECHA | P26: MOTIVO | R26: MONTO
A27: =WEEKDAY(D27,2) -> 3 | B27: 3 | C27: =D27 -> 45826 | D27: 45826 | E27: 0.375 | F27: 0.85416667 | G27: =F27-E27 -> 0.47916667 | H27: =IF(A27=1,$H$2,IF(A27=2,$H$4,IF(A27=3,$H$6,IF(A27=4,$H$8,IF(A27=5,$H$10,IF(A27=6,$H$12,IF(A27=7,$H$14))))))) -> 0.45833333 | I27: =G27-H27 -> 0.020833333 | J27: =I27*$L$19*24 -> 1.8181818 | R27: 100
A28: =WEEKDAY(D28,2) -> 4 | B28: 4 | C28: =D28 -> 45827 | D28: 45827 | E28: 0.38263889 | F28: 0.85416667 | G28: =F28-E28 -> 0.47152778 | H28: =IF(A28=1,$H$2,IF(A28=2,$H$4,IF(A28=3,$H$6,IF(A28=4,$H$8,IF(A28=5,$H$10,IF(A28=6,$H$12,IF(A28=7,$H$14))))))) -> 0 | I28: =G28-H28 -> 0.47152778 | J28: =I28*$L$19*24 -> 41.151515 | R28: 20
A29: =WEEKDAY(D29,2) -> 5 | B29: 5 | C29: =D29 -> 45828 | D29: 45828 | G29: =F29-E29 -> 0 | H29: =IF(A29=1,$H$2,IF(A29=2,$H$4,IF(A29=3,$H$6,IF(A29=4,$H$8,IF(A29=5,$H$10,IF(A29=6,$H$12,IF(A29=7,$H$14))))))) -> 0 | I29: =G29-H29 -> 0 | J29: =I29*$L$19*24 -> 0 | R29: 50
A30: =WEEKDAY(D30,2) -> 6 | B30: 6 | C30: =D30 -> 45829 | D30: 45829 | G30: =F30-E30 -> 0 | H30: =IF(A30=1,$H$2,IF(A30=2,$H$4,IF(A30=3,$H$6,IF(A30=4,$H$8,IF(A30=5,$H$10,IF(A30=6,$H$12,IF(A30=7,$H$14))))))) -> 0 | I30: =G30-H30 -> 0 | J30: =I30*$L$19*24 -> 0 | R30: 20 | T30: LUCEBIEN 2 (ESQUINA) | AF30: =SUM(U30:AE35) -> 0
A31: =WEEKDAY(D31,2) -> 7 | B31: 7 | C31: =D31 -> 45830 | D31: 45830 | G31: =F31-E31 -> 0 | H31: =IF(A31=1,$H$2,IF(A31=2,$H$4,IF(A31=3,$H$6,IF(A31=4,$H$8,IF(A31=5,$H$10,IF(A31=6,$H$12,IF(A31=7,$H$14))))))) -> 0 | I31: =G31-H31 -> 0 | J31: =I31*$L$19*24 -> 0
A32: =WEEKDAY(D32,2) -> 1 | B32: 8 | C32: =D32 -> 45831 | D32: 45831 | E32: 0.38263889 | F32: 0.83333333 | G32: =F32-E32 -> 0.45069444 | H32: =IF(A32=1,$H$2,IF(A32=2,$H$4,IF(A32=3,$H$6,IF(A32=4,$H$8,IF(A32=5,$H$10,IF(A32=6,$H$12,IF(A32=7,$H$14))))))) -> 0.45833333 | I32: =G32-H32 -> -0.0076388889 | J32: =I32*$L$19*24 -> -0.66666667
A33: =WEEKDAY(D33,2) -> 2 | B33: 9 | C33: =D33 -> 45832 | D33: 45832 | E33: 0.38263889 | F33: 0.85416667 | G33: =F33-E33 -> 0.47152778 | H33: =IF(A33=1,$H$2,IF(A33=2,$H$4,IF(A33=3,$H$6,IF(A33=4,$H$8,IF(A33=5,$H$10,IF(A33=6,$H$12,IF(A33=7,$H$14))))))) -> 0.45833333 | I33: =G33-H33 -> 0.013194444 | J33: =I33*$L$19*24 -> 1.1515152
A34: =WEEKDAY(D34,2) -> 3 | B34: 10 | C34: =D34 -> 45833 | D34: 45833 | E34: 0.375 | F34: 0.85416667 | G34: =F34-E34 -> 0.47916667 | H34: =IF(A34=1,$H$2,IF(A34=2,$H$4,IF(A34=3,$H$6,IF(A34=4,$H$8,IF(A34=5,$H$10,IF(A34=6,$H$12,IF(A34=7,$H$14))))))) -> 0.45833333 | I34: =G34-H34 -> 0.020833333 | J34: =I34*$L$19*24 -> 1.8181818
A35: =WEEKDAY(D35,2) -> 4 | B35: 11 | C35: =D35 -> 45834 | D35: 45834 | G35: =F35-E35 -> 0 | H35: =IF(A35=1,$H$2,IF(A35=2,$H$4,IF(A35=3,$H$6,IF(A35=4,$H$8,IF(A35=5,$H$10,IF(A35=6,$H$12,IF(A35=7,$H$14))))))) -> 0 | I35: =G35-H35 -> 0 | J35: =I35*$L$19*24 -> 0
A36: =WEEKDAY(D36,2) -> 5 | B36: 12 | C36: =D36 -> 45835 | D36: 45835 | G36: =F36-E36 -> 0 | H36: =IF(A36=1,$H$2,IF(A36=2,$H$4,IF(A36=3,$H$6,IF(A36=4,$H$8,IF(A36=5,$H$10,IF(A36=6,$H$12,IF(A36=7,$H$14))))))) -> 0 | I36: =G36-H36 -> 0 | J36: =I36*$L$19*24 -> 0 | T36: LUCEBIEN 3 TRECE | U36: 150 | AF36: =SUM(U36:AE41) -> 650
A37: =WEEKDAY(D37,2) -> 6 | B37: 13 | C37: =D37 -> 45836 | D37: 45836 | G37: =F37-E37 -> 0 | H37: =IF(A37=1,$H$2,IF(A37=2,$H$4,IF(A37=3,$H$6,IF(A37=4,$H$8,IF(A37=5,$H$10,IF(A37=6,$H$12,IF(A37=7,$H$14))))))) -> 0 | I37: =G37-H37 -> 0 | J37: =I37*$L$19*24 -> 0 | U37: 300
A38: =WEEKDAY(D38,2) -> 7 | B38: 14 | C38: =D38 -> 45837 | D38: 45837 | G38: =F38-E38 -> 0 | H38: =IF(A38=1,$H$2,IF(A38=2,$H$4,IF(A38=3,$H$6,IF(A38=4,$H$8,IF(A38=5,$H$10,IF(A38=6,$H$12,IF(A38=7,$H$14))))))) -> 0 | I38: =G38-H38 -> 0 | J38: =I38*$L$19*24 -> 0 | U38: 200
A39: =WEEKDAY(D39,2) -> 1 | B39: 15 | C39: =D39 -> 45838 | D39: 45838 | E39: 0.38263889 | F39: 0.83333333 | G39: =F39-E39 -> 0.45069444 | H39: =IF(A39=1,$H$2,IF(A39=2,$H$4,IF(A39=3,$H$6,IF(A39=4,$H$8,IF(A39=5,$H$10,IF(A39=6,$H$12,IF(A39=7,$H$14))))))) -> 0.45833333 | I39: =G39-H39 -> -0.0076388889 | J39: =I39*$L$19*24 -> -0.66666667
A40: =WEEKDAY(D40,2) -> 2 | B40: 16 | C40: =D40 -> 45839 | D40: 45839 | E40: 0.38263889 | F40: 0.85416667 | G40: =F40-E40 -> 0.47152778 | H40: =IF(A40=1,$H$2,IF(A40=2,$H$4,IF(A40=3,$H$6,IF(A40=4,$H$8,IF(A40=5,$H$10,IF(A40=6,$H$12,IF(A40=7,$H$14))))))) -> 0.45833333 | I40: =G40-H40 -> 0.013194444 | J40: =I40*$L$19*24 -> 1.1515152
...

Sheet RESUMEN
I5: DAR UN PLACA DE REGALO
B18: TOTAL DE VENTAS ACORDADO | C18: =DASHWORD!V7 -> 5100 | E18: FALTAS INJUSTIFICADAS | F18: =DASHWORD!Q4 -> 4
A19: X | B19: MÍNIMO DE VENTAS PARA CONTINUAR | C19: =PARAMETROS!G10 -> 4800 | E19: TARDANZAS SIN JUSTIFICAR | F19: =DASHWORD!Q10 -> 0
B20: TOTAL DE VENTAS LOGRADO | C20: =DASHWORD!Z21 -> 7200
B21: HORAS EXTRAS (SI ES POSITIVO SE SUMA CON BENEFICIOS; SI ES NEGATIVO SE SUMA A DESCUENTOS) | C21: =DASHWORD!Q61 -> 14.983333 | E21: CONTINUA CON EL TRABAJO | F21: =IF(C20>C19,"SI CONTUNUA","NO CONTINUA") -> SI CONTUNUA
B22: BENEFICIOS
B23: 1ERA COMISIÓN | C23: =DASHWORD!R50 -> 46.4
B24: 2DA COMISIÓN | C24: =DASHWORD!R51 -> 90
B25: ADICIONAL POR CAPACITACIÓN | C25: =DASHWORD!R62 -> 50
B26: DESCUENTOS
B27: PENALIDAD POR TARDANZAS | C27: =DASHWORD!R64 -> 20
B28: PENALIDAD DE FALTAS | C28: =DASHWORD!R57 -> 0 | E28: OBSERVACIONES
B29: REPORTES | C29: =DASHWORD!R23 -> -20
B30: SUELDO | C30: =DASHWORD!L17 -> 600
B31: TOTAL DE BENEFICIOS | C31: =C23+C24+C25 -> 186.4
B32: TOTAL DE DESCUENTOS | C32: =C28+C29 -> -20
B33: TOTAL FINAL POR PAGAR | C33: =C30+C31+C32 -> 766.4
B34: TOTAL DE ADELANTOS | C34: =SUM(DASHWORD!R27:R42) -> 190
B35: RESTANTE DE SUELDO | C35: =C33-C34 -> 576.4
B36: CANCELADO ¿SI O NO? | C36: =IF(C35=0,"SI","NO") -> NO
B38: SUMA DE ALMUERZOS | C38: =DASHWORD!R44 -> 0
B39: TOTAL FINAL INVERTIDO ADM. | C39: =C33+C38 -> 766.4

Sheet ACUERDOS
B2: ACUERDOS
B3: SEMANA DE GARANTÍA
B4: FECHAS DE PAGO | D4: 3 DE CADA MES
B5: SUELDO MENSUAL
B6: TIEMPO DE CONTRATO

Sheet PARAMETROS
A2: TIEMPO DE AUMENTO | B2: ESCALAS | C2: PRECIO x HORAS | D2: VA DEACUERDO A EVALUACIÓN | G2: META SEMANAL | H2: HORAS X DÍA | I2: Horas x semana
F3: MAÑAMA | G3: 1500 | H3: 5.5 | I3: =H3*6 -> 33 | J3: =G3/I3 -> 45.454545
A4: 1ER MES | B4: 1 | C4: 2.9 | F4: TARDE | G4: =J3*I4 -> 1772.7273 | H4: 6.5 | I4: =H4*6 -> 39 | J4: =G4/I4 -> 45.454545
B5: 2 | C5: 3.2 | F5: META X HORAS | G5: =J3 -> 45.454545
A6: 1ER, 2DO,3er MES | B6: 3 | C6: 3.5
A7: 5TO MES | B7: 4 | C7: 3.8
A8: 9NO MES | B8: 5 | C8: 5 | G8: MEDIO TIEMPO | H8: TIEMPO COMPLETO
F9: MAÑAMA | G9: =1000*4 -> 4000 | H9: =1800*4 -> 7200
F10: TARDE | G10: =1200*4 -> 4800

Sheet RESUMEN ENTREGABLE
